<?xml version="1.0" ?>


<robot name="linear_actuator">

    <!-- colors -->

    <gazebo reference="arm">
         <material>Gazebo/Black</material>
    </gazebo>

    <gazebo reference="base">
         <material>Gazebo/Orange</material>
    </gazebo>

    <link name="world"/>

    <joint name="fixed" type="fixed">
        <origin rpy="0 0 0" xyz="0 0.0 0.5" />
        <parent link="world"/>
        <child link="base"/>
    </joint>

 
   
    <link name ="base" >
    
      <inertial>
      
          <origin xyz="0 0 0.09" rpy="0 0 0" />
         
          <mass value="1.8"/>
      
            <inertia 
              ixx="0.108" 
              ixy="0" 
              ixz="0" 
              iyy="0.108" 
              iyz="0" 
              izz="0.054"
            />
        </inertial>
        


      <visual >

          <geometry>
              <mesh
         
                  filename="package://robot_description/models/linear_actuator_with_camera/STL/base.stl"
                  scale = "0.01 0.01 0.01"
                  
              />
          
          </geometry>
     
        
      
      </visual>
      <collision name='collision_base_link'>
    
          <geometry>
            <mesh

                filename="package://robot_description/models/linear_actuator_with_camera/STL/base.stl"
                scale = "0.01 0.01 0.01"
            />
       
          </geometry>
          
      </collision>
    </link>

    <link name ="arm" >
 
        <inertial>
        <origin xyz="0 0 0.09" rpy="0 0 0" />
            <mass value="1.8"/>
        <inertia 
            ixx="0.108" 
            ixy="0" 
            ixz="0" 
            iyy="0.108" 
            iyz="0" 
            izz="0.054"
        />
        </inertial>

        <visual>

            <geometry>
                <mesh
                    filename="package://robot_description/models/linear_actuator_with_camera/STL/arm.stl"
                    scale = "0.01 0.01 0.01"
                />
           
            </geometry>
      
           
      
        </visual>
        <collision name='collision_arm_link'>
    
            <geometry>
                <mesh
                        filename="package://robot_description/models/linear_actuator_with_camera/STL/arm.stl"
                        scale = "0.01 0.01 0.01"
                />
            
            </geometry>
        </collision>
    </link>

    <joint name="arm_base" type="prismatic">
        <origin rpy="0 0 0" xyz="0 0.6 0" />
        
        <parent link="base"/>
        <child link ="arm"/>
        
        <axis xyz="0 1 0"/>
        <limit  effort="1000" 
                lower="0" 
                upper="0.2" 
                velocity="2" />
             
        />
        <dynamics damping="0.1"/>
    </joint> 





    <link name="camera_base">
        <inertial>
          <mass value="1.0e-05" />
          <origin xyz="0 0 0" rpy="0 0 0"/>
          <inertia ixx="1.0e-06" ixy="0" ixz="0" iyy="1.0e-06" iyz="0" izz="1.0e-06" />
        </inertial>

        <visual>
      
            <geometry>
                <box size="0.05 0.05 0.05"/>
            </geometry>

        </visual>

        <collision>
       
            <geometry>
                <box size="0.05 0.05 0.05"/>
            </geometry>
        </collision>

        
    </link>  

    <joint name="camera_base_arm" type="fixed">
        <axis xyz="0 1 0" />
        <origin xyz="0 0.6 0" rpy="0 0 1.57"/>
        <parent link="arm"/>
        <child link="camera_base"/>
    </joint>

    <!-- plugin -->
      <gazebo>
    <plugin name="gazebo_ros_control" filename="libgazebo_ros_control.so">
        <!-- <robotNameSpace>/linear_actuator</robotNameSpace> -->
        <robotSimType>gazebo_ros_control/DefaultRobotHWSim</robotSimType>
    </plugin>
      </gazebo>

     <!-- transmission -->
    <transmission name="linear_transmission">
        <type>transmission_interface/SimpleTransmission</type>
        <joint name="arm_base">
          <hardwareInterface>PositionJointInterface</hardwareInterface>
        </joint>  
        <actuator name="linear_motor">
          <hardwareInterface>PositionJointInterface</hardwareInterface>
          <mechanicalReduction>1</mechanicalReduction>
        </actuator>
    </transmission>

    <!-- camera plugin  -->
     
    <gazebo reference="camera_base">
        <sensor type="camera" name="camera1">
          <update_rate>30.0</update_rate>
          <camera name="head">
            <horizontal_fov>1.3962634</horizontal_fov>
            <image>
              <width>800</width>
              <height>800</height>
              <format>R8G8B8</format>
            </image>
            <clip>
              <near>0.02</near>
              <far>300</far>
            </clip>
            <noise>
              <type>gaussian</type>
              <mean>0.0</mean>
              <stddev>0.007</stddev>
            </noise>
          </camera>

          <plugin name="camera_controller" filename="libgazebo_ros_camera.so">
            <alwaysOn>true</alwaysOn>
            <updateRate>0.0</updateRate>
            <cameraName>camera1</cameraName>
            <imageTopicName>image_raw</imageTopicName>
            <cameraInfoTopicName>camera_info</cameraInfoTopicName>
            <frameName>camera_base</frameName>
            <hackBaseline>0.07</hackBaseline>
            <distortionK1>0.0</distortionK1>
            <distortionK2>0.0</distortionK2>
            <distortionK3>0.0</distortionK3>
            <distortionT1>0.0</distortionT1>
            <distortionT2>0.0</distortionT2>
          </plugin>
        </sensor>
    </gazebo>

    
    


</robot>