<?xml version="1.0" ?>


<robot name="wheeler">

    <!-- gazebo -->

    <gazebo reference="arm">
        <material>Gazebo/Black</material>
    </gazebo>

    <gazebo reference="base">
        <material>Gazebo/Orange</material>
    </gazebo>

    <gazebo>
        <plugin name="skid_steer_drive_controller" filename="libgazebo_ros_skid_steer_drive.so">
            <updateRate>100.0</updateRate>
            <robotNamespace>/wheeler/</robotNamespace>
            
            <leftFrontJoint>chasis_fl_wheel</leftFrontJoint>
            <rightFrontJoint>chasis_fr_wheel</rightFrontJoint>
            <leftRearJoint>chasis_bl_wheel</leftRearJoint>
            <rightRearJoint>chasis_br_wheel</rightRearJoint>
            
            <wheelSeparation>0.65</wheelSeparation>
            <wheelDiameter>0.4</wheelDiameter>
            <robotBaseFrame></robotBaseFrame>
            <torque>20</torque>
            <commandTopic>cmd_vel</commandTopic>
            <odometryTopic>odom</odometryTopic>
            <broadcastTF>false</broadcastTF>
        </plugin>
    </gazebo>

    <gazebo>
        <plugin name="gazebo_ros_control" filename="libgazebo_ros_control.so">
            <!-- <robotNameSpace>/linear_actuator/</robotNameSpace> -->
            <robotSimType>gazebo_ros_control/DefaultRobotHWSim</robotSimType>
        </plugin>
    </gazebo>

    <gazebo reference="camera_base">
        <sensor type="camera" name="camera1">
          <update_rate>30.0</update_rate>
          <camera name="head">
            <horizontal_fov>1.3962634</horizontal_fov>
            <image>
              <width>800</width>
              <height>800</height>
              <format>R8G8B8</format>
            </image>
            <clip>
              <near>0.02</near>
              <far>300</far>
            </clip>
            <noise>
              <type>gaussian</type>
              <mean>0.0</mean>
              <stddev>0.007</stddev>
            </noise>
          </camera>

          <plugin name="camera_controller" filename="libgazebo_ros_camera.so">
            <alwaysOn>true</alwaysOn>
            <updateRate>0.0</updateRate>
            <cameraName>camera1</cameraName>
            <imageTopicName>image_raw</imageTopicName>
            <cameraInfoTopicName>camera_info</cameraInfoTopicName>
            <frameName>camera_base</frameName>
            <hackBaseline>0.07</hackBaseline>
            <distortionK1>0.0</distortionK1>
            <distortionK2>0.0</distortionK2>
            <distortionK3>0.0</distortionK3>
            <distortionT1>0.0</distortionT1>
            <distortionT2>0.0</distortionT2>
          </plugin>
        </sensor>
    </gazebo>

  
   

    <!-- main -->
    <link name ="chassis" >
    
        <inertial>

              <origin xyz="0 0 0.3" rpy="0 0 0" />

              <mass value="1"/>

                <inertia 
                  ixx="1.5417" 
                  ixy="0" 
                  ixz="0" 
                  iyy="3.467" 
                  iyz="0" 
                  izz="4.742"
                />
        </inertial>
        


      <visual >

          <geometry>
              
                <mesh   filename="package://robot_description/models/wheeler/STL/chassis.stl"  
                        scale="0.5 0.5 0.5"
                />
          
          </geometry>
     

      </visual>

      <collision>
    
          <geometry>
            
                <box size="1 0.65 0.2" />

          </geometry>
          
      </collision>
    </link>

    

        <link name="bl_wheel">
            <inertial>
        
                <origin xyz="0 0 0" rpy="0 0 0" />
        
                <mass value="1"/>
        
              <inertia 
                ixx="0.002526666666667" 
                ixy="0" 
                ixz="0" 
                iyy="0.002526666666667" 
                iyz="0" 
                izz="0.005"
              />
            </inertial>

            <!-- Tires -->
            <collision>
                <origin xyz="0 0.09 0" 
                        rpy="1.5707963267948966 0 0" />
                <geometry>
                    <cylinder length="0.06" radius="0.2"/>
                </geometry>
            </collision>
            
            <visual>
                <origin xyz="0 0.09 0" 
                    rpy="1.5707963267948966 0 0" />
                <geometry>
                    
                    <mesh   filename="package://robot_description/models/wheeler/STL/wheel.stl"  
                        scale="0.5 0.5 0.5"
                    />
        
                </geometry>
                <material name="Black">
                    <color rgba="0.1 0.1 0.1 1" />
                </material>
            </visual>

            <!-- Axle -->
            <collision>
                <origin xyz="0 0.03 0" 
                        rpy="1.5707963267948966 0 0" />
                <geometry>
                     <cylinder length="0.12" radius="0.04"/>
                </geometry>
            </collision>
            
            <visual>
                <origin xyz="0 0.03 0" 
                        rpy="1.5707963267948966 0 0" />
                <geometry>
                     <cylinder length="0.12" radius="0.04"/>
                </geometry>
                <material name="Grey">
                    <color rgba="0.6 0.6 0.6 1" />
                </material>
            </visual>

            <!-- Hubcap -->
            <visual>
                <origin xyz="0 0.09 0" 
                        rpy="1.5707963267948966 0 0" />
                <geometry>
                    <box size="0.01 0.25 0.01" />
                </geometry>
                <material name="Grey">
                    <color rgba="0.6 0.6 0.6 1" />
                </material>
            </visual>
        </link>


        <joint name="chasis_bl_wheel" type="continuous">
        <origin xyz="-0.3 0.325 0" 
                rpy="0 0 0" />
            <child link="bl_wheel" />
            <parent link="chassis" />
            <axis xyz="0 1 0" 
                    rpy="0 0 0" />
            <limit effort="10000" velocity="1000" />
            <joint_properties damping="1" friction="1" />
        </joint>

    

        <link name="br_wheel">
            <inertial>
        
                <origin xyz="0 0 0" rpy="0 0 0" />
        
                <mass value="1"/>
        
              <inertia 
                ixx="0.002526666666667" 
                ixy="0" 
                ixz="0" 
                iyy="0.002526666666667" 
                iyz="0" 
                izz="0.005"
              />
            </inertial>

            <!-- Tires -->
            <collision>
                <origin xyz="0 -0.09 0" 
                        rpy="1.5707963267948966 0 0" />
                <geometry>
                    <cylinder length="0.06" radius="0.2"/>
                </geometry>
            </collision>
            
            <visual>
                <origin xyz="0 -0.09 0" 
                    rpy="1.5707963267948966 0 0" />
                <geometry>
                    
                    <mesh   filename="package://robot_description/models/wheeler/STL/wheel.stl"  
                        scale="0.5 0.5 0.5"
                    />
        
                </geometry>
                <material name="Black">
                    <color rgba="0.1 0.1 0.1 1" />
                </material>
            </visual>

            <!-- Axle -->
            <collision>
                <origin xyz="0 -0.03 0" 
                        rpy="1.5707963267948966 0 0" />
                <geometry>
                     <cylinder length="0.12" radius="0.04"/>
                </geometry>
            </collision>
            
            <visual>
                <origin xyz="0 -0.03 0" 
                        rpy="1.5707963267948966 0 0" />
                <geometry>
                     <cylinder length="0.12" radius="0.04"/>
                </geometry>
                <material name="Grey">
                    <color rgba="0.6 0.6 0.6 1" />
                </material>
            </visual>

            <!-- Hubcap -->
            <visual>
                <origin xyz="0 -0.09 0" 
                        rpy="1.5707963267948966 0 0" />
                <geometry>
                    <box size="0.01 0.25 0.01" />
                </geometry>
                <material name="Grey">
                    <color rgba="0.6 0.6 0.6 1" />
                </material>
            </visual>
        </link>


        <joint name="chasis_br_wheel" type="continuous">
        <origin xyz="-0.3 -0.325 0" 
                rpy="0 0 0" />
            <child link="br_wheel" />
            <parent link="chassis" />
            <axis xyz="0 1 0" 
                    rpy="0 0 0" />
            <limit effort="10000" velocity="1000" />
            <joint_properties damping="1" friction="1" />
        </joint>

    

        <link name="fl_wheel">
            <inertial>
        
                <origin xyz="0 0 0" rpy="0 0 0" />
        
                <mass value="1"/>
        
              <inertia 
                ixx="0.002526666666667" 
                ixy="0" 
                ixz="0" 
                iyy="0.002526666666667" 
                iyz="0" 
                izz="0.005"
              />
            </inertial>

            <!-- Tires -->
            <collision>
                <origin xyz="0 0.09 0" 
                        rpy="1.5707963267948966 0 0" />
                <geometry>
                    <cylinder length="0.06" radius="0.2"/>
                </geometry>
            </collision>
            
            <visual>
                <origin xyz="0 0.09 0" 
                    rpy="1.5707963267948966 0 0" />
                <geometry>
                    
                    <mesh   filename="package://robot_description/models/wheeler/STL/wheel.stl"  
                        scale="0.5 0.5 0.5"
                    />
        
                </geometry>
                <material name="Black">
                    <color rgba="0.1 0.1 0.1 1" />
                </material>
            </visual>

            <!-- Axle -->
            <collision>
                <origin xyz="0 0.03 0" 
                        rpy="1.5707963267948966 0 0" />
                <geometry>
                     <cylinder length="0.12" radius="0.04"/>
                </geometry>
            </collision>
            
            <visual>
                <origin xyz="0 0.03 0" 
                        rpy="1.5707963267948966 0 0" />
                <geometry>
                     <cylinder length="0.12" radius="0.04"/>
                </geometry>
                <material name="Grey">
                    <color rgba="0.6 0.6 0.6 1" />
                </material>
            </visual>

            <!-- Hubcap -->
            <visual>
                <origin xyz="0 0.09 0" 
                        rpy="1.5707963267948966 0 0" />
                <geometry>
                    <box size="0.01 0.25 0.01" />
                </geometry>
                <material name="Grey">
                    <color rgba="0.6 0.6 0.6 1" />
                </material>
            </visual>
        </link>


        <joint name="chasis_fl_wheel" type="continuous">
        <origin xyz="0.3 0.325 0" 
                rpy="0 0 0" />
            <child link="fl_wheel" />
            <parent link="chassis" />
            <axis xyz="0 1 0" 
                    rpy="0 0 0" />
            <limit effort="10000" velocity="1000" />
            <joint_properties damping="1" friction="1" />
        </joint>

    

        <link name="fr_wheel">
            <inertial>
        
                <origin xyz="0 0 0" rpy="0 0 0" />
        
                <mass value="1"/>
        
              <inertia 
                ixx="0.002526666666667" 
                ixy="0" 
                ixz="0" 
                iyy="0.002526666666667" 
                iyz="0" 
                izz="0.005"
              />
            </inertial>

            <!-- Tires -->
            <collision>
                <origin xyz="0 -0.09 0" 
                        rpy="1.5707963267948966 0 0" />
                <geometry>
                    <cylinder length="0.06" radius="0.2"/>
                </geometry>
            </collision>
            
            <visual>
                <origin xyz="0 -0.09 0" 
                    rpy="1.5707963267948966 0 0" />
                <geometry>
                    
                    <mesh   filename="package://robot_description/models/wheeler/STL/wheel.stl"  
                        scale="0.5 0.5 0.5"
                    />
        
                </geometry>
                <material name="Black">
                    <color rgba="0.1 0.1 0.1 1" />
                </material>
            </visual>

            <!-- Axle -->
            <collision>
                <origin xyz="0 -0.03 0" 
                        rpy="1.5707963267948966 0 0" />
                <geometry>
                     <cylinder length="0.12" radius="0.04"/>
                </geometry>
            </collision>
            
            <visual>
                <origin xyz="0 -0.03 0" 
                        rpy="1.5707963267948966 0 0" />
                <geometry>
                     <cylinder length="0.12" radius="0.04"/>
                </geometry>
                <material name="Grey">
                    <color rgba="0.6 0.6 0.6 1" />
                </material>
            </visual>

            <!-- Hubcap -->
            <visual>
                <origin xyz="0 -0.09 0" 
                        rpy="1.5707963267948966 0 0" />
                <geometry>
                    <box size="0.01 0.25 0.01" />
                </geometry>
                <material name="Grey">
                    <color rgba="0.6 0.6 0.6 1" />
                </material>
            </visual>
        </link>


        <joint name="chasis_fr_wheel" type="continuous">
        <origin xyz="0.3 -0.325 0" 
                rpy="0 0 0" />
            <child link="fr_wheel" />
            <parent link="chassis" />
            <axis xyz="0 1 0" 
                    rpy="0 0 0" />
            <limit effort="10000" velocity="1000" />
            <joint_properties damping="1" friction="1" />
        </joint>

    


     
    <link name ="base" >
    
      <inertial>
      
          <origin xyz="0 0 0.09" rpy="0 0 0" />
         
          <mass value="1.8"/>
      
            <inertia 
              ixx="0.108" 
              ixy="0" 
              ixz="0" 
              iyy="0.108" 
              iyz="0" 
              izz="0.054"
            />
        </inertial>
        


      <visual >

          <geometry>
              <mesh
         
                  filename="package://robot_description/models/poker/STL/base.stl"
                  scale = "0.01 0.01 0.01"
                  
              />
          
          </geometry>
     
        
      
      </visual>
      <collision name='collision_base_link'>
    
          <geometry>
            <mesh

                filename="package://robot_description/models/poker/STL/base.stl"
                scale = "0.01 0.01 0.01"
            />
       
          </geometry>
          
      </collision>
    </link>

    <joint name="chassis_base" type="fixed">
        <origin rpy="0 0 0" xyz="0 0 0.15" />
        
        <parent link="chassis"/>
        <child link ="base"/>
        
    </joint> 

    <link name ="arm" >
 
        <inertial>
        <origin xyz="0 0 0.09" rpy="0 0 0" />
            <mass value="1.8"/>
        <inertia 
            ixx="0.108" 
            ixy="0" 
            ixz="0" 
            iyy="0.108" 
            iyz="0" 
            izz="0.054"
        />
        </inertial>

        <visual>

            <geometry>
                <mesh
                    filename="package://robot_description/models/poker/STL/arm.stl"
                    scale = "0.01 0.01 0.01"
                />
           
            </geometry>
      
           
      
        </visual>
        <collision name='collision_arm_link'>
    
            <geometry>
                <mesh
                        filename="package://robot_description/models/poker/STL/arm.stl"
                        scale = "0.01 0.01 0.01"
                />
            
            </geometry>
        </collision>
    </link>

    <joint name="arm_base" type="prismatic">
        <origin rpy="0 0 0" xyz="0 0.3 0" />
        
        <parent link="base"/>
        <child link ="arm"/>
        
        <axis xyz="0 1 0"/>
        <limit  effort="10000" 
                lower="0" 
                upper="0.5" 
                velocity="2" />
             
        />
        <dynamics damping="0.1"/>
    </joint> 

    <link name="camera_base">
        <inertial>
          <mass value="1.0e-05" />
          <origin xyz="0 0 0" rpy="0 0 0"/>
          <inertia ixx="1.0e-06" ixy="0" ixz="0" iyy="1.0e-06" iyz="0" izz="1.0e-06" />
        </inertial>

        <visual>
        
            <geometry>
                <box size="0.05 0.05 0.05"/>
            </geometry>

        </visual>

        <collision>
        
            <geometry>
                <box size="0.05 0.05 0.05"/>
            </geometry>
        </collision>

        
    </link>  

    <joint name="camera_base_arm" type="fixed">
        <axis xyz="0 1 0" />
        <origin xyz="0 0.6 -0.1" rpy="0 0 1.57"/>
        <parent link="arm"/>
        <child link="camera_base"/>
    </joint>


  
    <transmission name="linear_transmission">
        <type>transmission_interface/SimpleTransmission</type>
        <joint name="arm_base">
          <hardwareInterface>PositionJointInterface</hardwareInterface>
        </joint>  
        <actuator name="linear_motor">
          <hardwareInterface>PositionJointInterface</hardwareInterface>
          <mechanicalReduction>1</mechanicalReduction>
        </actuator>
    </transmission>



 
    

  


  

 
 


</robot>